<?xml version='1.0'?>
<sdf version='1.6'>
  <model name="miniscout">
    <pose>0 0 0.1 0 0 0</pose>
    <link name='body'>
      <inertial>
        <pose>-0.11 0 0 0 0 0</pose>
        <mass>0.165</mass>
        <inertia>
          <ixx>3e-3</ixx>
          <iyy>1e-2</iyy>
          <izz>1e-2</izz>
        </inertia>
      </inertial>
      <collision name='collision'>
        <geometry>
          <mesh>
            <scale>0.01 0.01 0.01</scale>
            <uri>model://miniscout/meshes/stl/body.stl</uri>
          </mesh>
        </geometry>
        <surface>
          <friction>
            <ode>
              <mu>0.2</mu>
              <mu2>0.2</mu2>
            </ode>
          </friction>
          <contact>
            <ode>
              <max_vel>0.1</max_vel>
              <min_depth>0.001</min_depth>
            </ode>
          </contact>
        </surface>
      </collision>
      <visual name='visual-body'>
        <geometry>
          <mesh>
            <scale>0.01 0.01 0.01</scale>
            <uri>model://miniscout/meshes/stl/body.stl</uri>
          </mesh>
        </geometry>
        <material>
          <ambient>0.678 0.529 0.384 1</ambient>
          <diffuse>0.678 0.529 0.384 1</diffuse>
          <specular>0.678 0.529 0.384 1</specular>
        </material>
      </visual>
      <visual name='visual-canopy'>
        <cast_shadows>0</cast_shadows>
        <geometry>
          <mesh>
            <scale>0.01 0.01 0.01</scale>
            <uri>model://miniscout/meshes/stl/canopy.stl</uri>
          </mesh>
        </geometry>
        <material>
          <script>
            <name>Gazebo/White</name>
          </script>
        </material>
      </visual>
      <visual name='visual-motor'>
        <cast_shadows>0</cast_shadows>
        <geometry>
          <mesh>
            <scale>0.01 0.01 0.01</scale>
            <uri>model://miniscout/meshes/stl/motor.stl</uri>
          </mesh>
        </geometry>
        <material>
          <script>
            <name>Gazebo/DarkGrey</name>
          </script>
        </material>
      </visual>

      <visual name='visual-gear-wire'>
       <pose>-0.07 0 0 0 0 0</pose>
        <cast_shadows>0</cast_shadows>
        <geometry>
          <mesh>
            <scale>0.01 0.01 0.01</scale>
            <uri>model://miniscout/meshes/stl/gear_wire.stl</uri>
          </mesh>
        </geometry>
        <material>
          <script>
            <name>Gazebo/DarkGrey</name>
          </script>
        </material>
      </visual>

        <visual name="cp_left_wing">
          <cast_shadows>0</cast_shadows>
          <pose>-0.12 0.15 0.02 0 0 0</pose>
          <geometry>
            <sphere><radius>0.01</radius></sphere>
          </geometry>
        </visual>

        <visual name="cp_right_wing">
          <cast_shadows>0</cast_shadows>
          <pose>-0.12 -0.15 0.02 0 0 0</pose>
          <geometry>
            <sphere><radius>0.01</radius></sphere>
          </geometry>
        </visual>

        <visual name="cp_htail">
          <cast_shadows>0</cast_shadows>
          <pose>-0.38 0.0 0.02 0 0 0</pose>
          <geometry>
            <sphere><radius>0.01</radius></sphere>
          </geometry>
        </visual>

        <visual name="cp_vtail">
          <cast_shadows>0</cast_shadows>
          <pose>-0.38 0.0 0.05 0 0 0</pose>
          <geometry>
            <sphere><radius>0.01</radius></sphere>
          </geometry>
        </visual>

    </link>
    <link name='imu_link'>
      <pose>-0.11 0 0 0 0 0</pose>
      <inertial>
        <mass>0.01</mass>
        <inertia>
          <ixx>1e-05</ixx>
          <iyy>1e-05</iyy>
          <izz>1e-05</izz>
        </inertia>
      </inertial>
    </link>
    <joint name='imu_joint' type='revolute'>
      <child>imu_link</child>
      <parent>body</parent>
      <axis>
        <xyz>1 0 0</xyz>
        <limit>
          <lower>0</lower>
          <upper>0</upper>
          <effort>0</effort>
          <velocity>0</velocity>
        </limit>
        <dynamics>
          <spring_reference>0</spring_reference>
          <spring_stiffness>0</spring_stiffness>
        </dynamics>
        <use_parent_model_frame>1</use_parent_model_frame>
      </axis>
    </joint>

    <!--<link name='rear_wheel'>-->
      <!--<pose>-0.40 0 0 0.0 0 0</pose>-->
      <!--<inertial>-->
        <!--<mass>0.001</mass>-->
        <!--<inertia>-->
          <!--<ixx>1e-6</ixx>-->
          <!--<iyy>1e-7</iyy>-->
          <!--<izz>1e-6</izz>-->
        <!--</inertia>-->
      <!--</inertial>-->
      <!--<visual name='rear-left-wheel'>-->
        <!--<cast_shadows>0</cast_shadows>-->
        <!--<geometry>-->
          <!--<mesh>-->
            <!--<scale>0.005 0.01 0.005</scale>-->
            <!--<uri>model://miniscout/meshes/stl/wheel.stl</uri>-->
          <!--</mesh>-->
        <!--</geometry>-->
        <!--<material>-->
          <!--<script>-->
            <!--<name>Gazebo/Grey</name>-->
          <!--</script>-->
        <!--</material>-->
      <!--</visual>-->
      <!--<visual name='rear-left-tire'>-->
        <!--<cast_shadows>0</cast_shadows>-->
        <!--<geometry>-->
          <!--<mesh>-->
            <!--<scale>0.005 0.01 0.005</scale>-->
            <!--<uri>model://miniscout/meshes/stl/tire.stl</uri>-->
          <!--</mesh>-->
        <!--</geometry>-->
        <!--<material>-->
          <!--<script>-->
            <!--<name>Gazebo/White</name>-->
          <!--</script>-->
        <!--</material>-->
      <!--</visual>-->
      <!--<collision name='collision'>-->
        <!--<pose>0 0 0 1.57 0 0</pose>-->
        <!--<geometry>-->
          <!--<cylinder> -->
            <!--<radius>0.025</radius>-->
            <!--<length>0.01</length>-->
          <!--</cylinder>-->
        <!--</geometry>-->
        <!--<surface>-->
          <!--<friction>-->
            <!--<ode>-->
              <!--<mu>0.3</mu>-->
              <!--<mu2>0.3</mu2>-->
            <!--</ode>-->
          <!--</friction>-->
          <!--<contact>-->
            <!--<ode>-->
              <!--<max_vel>0.1</max_vel>-->
              <!--<min_depth>0.001</min_depth>-->
            <!--</ode>-->
          <!--</contact>-->
        <!--</surface>-->
      <!--</collision>-->
    <!--</link>-->

    <!--<joint name='rear_wheel_joint' type='revolute'>-->
      <!--<parent>gear</parent>-->
      <!--<child>rear_wheel</child>-->
      <!--<axis>-->
        <!--<xyz>0 1 0</xyz>-->
      <!--</axis>-->
    <!--</joint>-->

    <link name='left_wheel'>
      <pose>-0.07 -0.05 -0.065 0.0 0 0</pose>
      <inertial>
        <mass>0.001</mass>
        <inertia>
          <ixx>1e-6</ixx>
          <iyy>1e-7</iyy>
          <izz>1e-6</izz>
        </inertia>
      </inertial>
      <visual name='visual-left-wheel'>
        <cast_shadows>0</cast_shadows>
        <geometry>
          <mesh>
            <scale>0.01 0.01 0.01</scale>
            <uri>model://miniscout/meshes/stl/wheel.stl</uri>
          </mesh>
        </geometry>
        <material>
          <script>
            <name>Gazebo/Grey</name>
          </script>
        </material>
      </visual>
      <visual name='visual-left-tire'>
        <cast_shadows>0</cast_shadows>
        <geometry>
          <mesh>
            <scale>0.01 0.01 0.01</scale>
            <uri>model://miniscout/meshes/stl/tire.stl</uri>
          </mesh>
        </geometry>
        <material>
          <script>
            <name>Gazebo/White</name>
          </script>
        </material>
      </visual>
      <collision name='collision'>
        <pose>0 0 0 1.57 0 0</pose>
        <geometry>
          <cylinder> 
            <radius>0.025</radius>
            <length>0.02</length>
          </cylinder>
        </geometry>
        <surface>
          <friction>
            <ode>
              <mu>0.3</mu>
              <mu2>0.3</mu2>
            </ode>
          </friction>
          <contact>
            <ode>
              <max_vel>0.1</max_vel>
              <min_depth>0.001</min_depth>
            </ode>
          </contact>
        </surface>
      </collision>
    </link>

    <joint name='left_wheel_joint' type='revolute'>
      <parent>body</parent>
      <child>left_wheel</child>
      <axis>
        <xyz>0 1 0</xyz>
      </axis>
    </joint>

    <link name='right_wheel'>
      <pose>-0.07 0.05 -0.065 -0.0 0 0</pose>
      <inertial>
        <mass>0.001</mass>
        <inertia>
          <ixx>1e-6</ixx>
          <iyy>1e-7</iyy>
          <izz>1e-6</izz>
        </inertia>
      </inertial>
      <visual name='visual-right-wheel'>
        <cast_shadows>0</cast_shadows>
        <geometry>
          <mesh>
            <scale>0.01 0.01 0.01</scale>
            <uri>model://miniscout/meshes/stl/wheel.stl</uri>
          </mesh>
        </geometry>
        <material>
          <script>
            <name>Gazebo/Grey</name>
          </script>
        </material>
      </visual>
      <visual name='visual-right-tire'>
        <cast_shadows>0</cast_shadows>
        <geometry>
          <mesh>
            <scale>0.01 0.01 0.01</scale>
            <uri>model://miniscout/meshes/stl/tire.stl</uri>
          </mesh>
        </geometry>
        <material>
          <script>
            <name>Gazebo/White</name>
          </script>
        </material>
      </visual>
      <collision name='collision'>
        <pose>0 0 0 1.57 0 0</pose>
        <geometry>
          <cylinder> 
            <radius>0.025</radius>
            <length>0.02</length>
          </cylinder>
        </geometry>
        <surface>
          <friction>
            <ode>
              <mu>0.3</mu>
              <mu2>0.3</mu2>
            </ode>
          </friction>
          <contact>
            <ode>
              <max_vel>0.1</max_vel>
              <min_depth>0.001</min_depth>
            </ode>
          </contact>
        </surface>
      </collision>
    </link>

    <joint name='right_wheel_joint' type='revolute'>
      <parent>body</parent>
      <child>right_wheel</child>
      <axis>
        <xyz>0 1 0</xyz>
      </axis>
    </joint>

    <link name='rudder'>
      <pose>-0.421 0 0.023 0 0 0 </pose>
      <inertial>
        <pose>-0.02 0 0 0 0 0</pose>
        <mass>0.001</mass>
        <inertia>
          <ixx>1e-6</ixx>
          <iyy>1e-6</iyy>
          <izz>1e-6</izz>
        </inertia>
      </inertial>
      <visual name='visual'>
        <cast_shadows>0</cast_shadows>
        <geometry>
          <mesh>
            <scale>0.01 0.01 0.01</scale>
            <uri>model://miniscout/meshes/stl/rudder.stl</uri>
          </mesh>
        </geometry>
        <material>
          <ambient>0.678 0.529 0.384 1</ambient>
          <diffuse>0.678 0.529 0.384 1</diffuse>
          <specular>0.678 0.529 0.384 1</specular>
        </material>
      </visual>
    </link>

    <link name='elevator'>
      <pose>-0.421 0 0.023 0 0 0 </pose>
      <inertial>
        <pose>-0.02 0 0 0 0 0</pose>
        <mass>0.001</mass>
        <inertia>
          <ixx>1e-6</ixx>
          <iyy>1e-6</iyy>
          <izz>1e-6</izz>
        </inertia>
      </inertial>
      <visual name='visual'>
        <cast_shadows>0</cast_shadows>
        <geometry>
          <mesh>
            <scale>0.01 0.01 0.01</scale>
            <uri>model://miniscout/meshes/stl/elevator.stl</uri>
          </mesh>
        </geometry>
        <material>
          <ambient>0.678 0.529 0.384 1</ambient>
          <diffuse>0.678 0.529 0.384 1</diffuse>
          <specular>0.678 0.529 0.384 1</specular>
        </material>
      </visual>
    </link>

    <link name='propeller'>
      <pose>0.01 0 0.01 0 0 -0.087</pose>
      <inertial>
        <mass>0.001</mass>
        <inertia>
          <ixx>1e-6</ixx>
          <iyy>1e-6</iyy>
          <izz>1e-6</izz>
        </inertia>
      </inertial>
      <visual name='visual'>
        <pose>0 0 0 0 1.57 0</pose>
        <cast_shadows>0</cast_shadows>
        <geometry>
          <mesh>
            <scale>0.5 0.5 0.5</scale>
            <uri>model://miniscout/meshes/iris_prop_ccw.dae</uri>
          </mesh>
        </geometry>
        <material>
          <script>
            <name>Gazebo/DarkGrey</name>
          </script>
        </material>
      </visual>
        <!--<visual name="cp_top">-->
          <!--<cast_shadows>0</cast_shadows>-->
          <!--<pose>0 0 0.05 0 0 0 0</pose>-->
          <!--<geometry>-->
            <!--<sphere><radius>0.01</radius></sphere>-->
          <!--</geometry>-->
        <!--</visual>-->
        <!--<visual name="cp_bottom">-->
          <!--<cast_shadows>0</cast_shadows>-->
          <!--<pose>0 0 -0.05 0 0 0 0</pose>-->
          <!--<geometry>-->
            <!--<sphere><radius>0.01</radius></sphere>-->
          <!--</geometry>-->
        <!--</visual>-->
    </link>

    <joint name='elevator_joint' type='revolute'>
      <parent>body</parent>
      <child>elevator</child>
      <axis>
        <xyz>0 1 0</xyz>
        <dynamics>
          <damping>1.000</damping>
        </dynamics>
      </axis>
      <physics>
        <ode>
          <implicit_spring_damper>1</implicit_spring_damper>
        </ode>
      </physics>
    </joint>

    <joint name='rudder_joint' type='revolute'>
      <parent>body</parent>
      <child>rudder</child>
      <axis>
        <xyz>0 0 1</xyz>
        <dynamics>
          <damping>1.000</damping>
        </dynamics>
      </axis>
      <physics>
        <ode>
          <implicit_spring_damper>1</implicit_spring_damper>
        </ode>
      </physics>
    </joint>

    <joint name='propeller_joint' type='revolute'>
      <parent>body</parent>
      <child>propeller</child>
      <axis>
        <xyz>1 0 0</xyz>
      </axis>
    </joint>

    <!--<plugin name="propeller_top_blade" filename="libLiftDragPlugin.so">-->
      <!--<a0>0.4</a0>-->
      <!--<cla>4.752798721</cla>-->
      <!--<cda>0.6417112299</cda>-->
      <!--<cma>0</cma>-->
      <!--<alpha_stall>1.5</alpha_stall>-->
      <!--<cla_stall>-3.85</cla_stall>-->
      <!--<cda_stall>-0.9233984055</cda_stall>-->
      <!--<cma_stall>0</cma_stall>-->
      <!--<cp>0 0 0.05</cp>-->
      <!--<area>2e-4</area>-->
      <!--<air_density>1.2041</air_density>-->
      <!--<forward>0 -1 0</forward>-->
      <!--<upward>1 0 0</upward>-->
      <!--<link_name>propeller</link_name>-->
    <!--</plugin>-->

    <!--<plugin name="propeller_bottom_blade" filename="libLiftDragPlugin.so">-->
      <!--<a0>0.4</a0>-->
      <!--<cla>4.752798721</cla>-->
      <!--<cda>0.6417112299</cda>-->
      <!--<cma>0</cma>-->
      <!--<alpha_stall>1.5</alpha_stall>-->
      <!--<cla_stall>-3.85</cla_stall>-->
      <!--<cda_stall>-0.9233984055</cda_stall>-->
      <!--<cma_stall>0</cma_stall>-->
      <!--<cp>0 0 -0.05</cp>-->
      <!--<area>2e-4</area>-->
      <!--<air_density>1.2041</air_density>-->
      <!--<forward>0 1 0</forward>-->
      <!--<upward>1 0 0</upward>-->
      <!--<link_name>propeller</link_name>-->
    <!--</plugin>-->

    <plugin name="left_wing" filename="libLiftDragPlugin.so">
      <a0>0.05984281113</a0>
      <cla>4.752798721</cla>
      <cda>0.6417112299</cda>
      <cma>-1.8</cma>
      <alpha_stall>0.3391428111</alpha_stall>
      <cla_stall>-3.85</cla_stall>
      <cda_stall>-0.9233984055</cda_stall>
      <cma_stall>0</cma_stall>
      <cp>-0.12 0.15 0.02</cp>
      <area>0.0425</area>
      <air_density>1.2041</air_density>
      <forward>1 0 0</forward>
      <upward>0 -0.087 0.996</upward>
      <link_name>body</link_name>
      <!--<control_joint_name>left_aileron_joint</control_joint_name>-->
      <!--<control_joint_rad_to_cl>-2.0</control_joint_rad_to_cl>-->
    </plugin>

    <plugin name="right_wing" filename="libLiftDragPlugin.so">
      <a0>0.05984281113</a0>
      <cla>4.752798721</cla>
      <cda>0.6417112299</cda>
      <cma>-1.8</cma>
      <alpha_stall>0.3391428111</alpha_stall>
      <cla_stall>-3.85</cla_stall>
      <cda_stall>-0.9233984055</cda_stall>
      <cma_stall>0</cma_stall>
      <cp>-0.12 -0.15 0.02</cp>
      <area>0.0425</area>
      <air_density>1.2041</air_density>
      <forward>1 0 0</forward>
      <upward>0 0.087 0.996</upward>
      <link_name>body</link_name>
      <!--<control_joint_name>-->
        <!--right_aileron_joint-->
      <!--</control_joint_name>-->
      <!--<control_joint_rad_to_cl>-2.0</control_joint_rad_to_cl>-->
    </plugin>

    <plugin name="htail" filename="libLiftDragPlugin.so">
      <a0>0.0</a0>
      <cla>4.75</cla>
      <cda>0.6417112299</cda>
      <cma>-1.8</cma>
      <alpha_stall>0.3391428111</alpha_stall>
      <cla_stall>-3.85</cla_stall>
      <cda_stall>-0.9233984055</cda_stall>
      <cma_stall>0</cma_stall>
      <cp>-0.38 0 0.02</cp>
      <area>0.02</area>
      <air_density>1.2041</air_density>
      <forward>1 0 0</forward>
      <upward>0 0 1</upward>
      <link_name>body</link_name>
      <control_joint_name>elevator_joint</control_joint_name>
      <control_joint_rad_to_cl>-4.0</control_joint_rad_to_cl>
    </plugin>

    <plugin name="vtail" filename="libLiftDragPlugin.so">
      <a0>0</a0>
      <cla>4.75</cla>
      <cda>0.6417112299</cda>
      <cma>-1.8</cma>
      <alpha_stall>0.3391428111</alpha_stall>
      <cla_stall>-3.85</cla_stall>
      <cda_stall>-0.9233984055</cda_stall>
      <cma_stall>0</cma_stall>
      <cp>-0.38 0 0.05</cp>
      <area>0.01</area>
      <air_density>1.2041</air_density>
      <forward>1 0 0</forward>
      <upward>0 1 0</upward>
      <link_name>body</link_name>
      <control_joint_name>rudder_joint</control_joint_name>
      <control_joint_rad_to_cl>4.0</control_joint_rad_to_cl>
    </plugin>

    <!--<plugin name="plane_plugin" filename="libPlanePlugin.so">-->
      <!--<engine>-->
        <!--<joint_name>propeller_joint</joint_name>-->
        <!--<inc_key>101</inc_key>-->
        <!--<dec_key>113</dec_key>-->
        <!--<inc_val>0.1</inc_val>-->
        <!--<min_val>0.0</min_val>-->
        <!--<max_val>1.0</max_val>-->
        <!--<prop_name>propeller</prop_name>-->
        <!--<diameter>6</diameter> [> inches <]-->
        <!--<ct>0.1893 -0.0023 -0.4128 0.2894 -0.0921</ct>-->
        <!--<cp>0.1518 -0.2083 0.3144 -0.3632 0.0912</cp>-->
        <!--<kV>2280</kV>-->
        <!--<i0>0.5</i0>-->
        <!--<iMax>20</iMax>-->
        <!--<r0>0.098</r0>-->
        <!--<battV>7.4</battV> [> used to saturate voltage <]-->
        <!--<axis_num>0</axis_num> [> axis of rotation, x-0, y-1, z-2 <]-->
      <!--</engine>-->
      <!--<control name="elevator_control">-->
        <!--<joint_name>elevator_joint</joint_name>-->
        <!--<inc_key>115</inc_key>-->
        <!--<dec_key>119</dec_key>-->
        <!--<inc_val>0.1</inc_val>-->
        <!--<min_val>-0.4</min_val>-->
        <!--<max_val>0.4</max_val>-->
        <!--<p>100</p>-->
        <!--<i>0</i>-->
        <!--<d>0</d>-->
        <!--<cmd_max>-0.4</cmd_max>-->
        <!--<cmd_min>0.4</cmd_min>-->
      <!--</control>-->
      <!--<control name="rudder_control">-->
        <!--<joint_name>rudder_joint</joint_name>-->
        <!--<inc_key>100</inc_key>-->
        <!--<inc_val>0.1</inc_val>-->
        <!--<dec_key>97</dec_key>-->
        <!--<min_val>-0.4</min_val>-->
        <!--<max_val>0.4</max_val>-->
        <!--<p>100</p>-->
        <!--<i>0</i>-->
        <!--<d>0</d>-->
        <!--<cmd_max>-0.4</cmd_max>-->
        <!--<cmd_min>0.4</cmd_min>-->
      <!--</control>-->
    <!--</plugin>-->

    <plugin name='gazebo_imu_plugin' filename='libgazebo_imu_plugin.so'>
      <robotNamespace></robotNamespace>
      <linkName>imu_link</linkName>
      <imuTopic>/imu</imuTopic>
      <gyroscopeNoiseDensity>0.0003394</gyroscopeNoiseDensity>
      <gyroscopeRandomWalk>3.8785e-05</gyroscopeRandomWalk>
      <gyroscopeBiasCorrelationTime>1000.0</gyroscopeBiasCorrelationTime>
      <gyroscopeTurnOnBiasSigma>0.0087</gyroscopeTurnOnBiasSigma>
      <accelerometerNoiseDensity>0.004</accelerometerNoiseDensity>
      <accelerometerRandomWalk>0.006</accelerometerRandomWalk>
      <accelerometerBiasCorrelationTime>300.0</accelerometerBiasCorrelationTime>
      <accelerometerTurnOnBiasSigma>0.196</accelerometerTurnOnBiasSigma>
    </plugin>

    <plugin name="gps_plugin" filename="libgazebo_gps_plugin.so">
        <robotNamespace></robotNamespace>
        <gpsNoise>true</gpsNoise>
    </plugin>

    <plugin name='magnetometer_plugin' filename='libgazebo_magnetometer_plugin.so'>
      <robotNamespace/>
      <pubRate>100</pubRate>
      <noiseDensity>0.0004</noiseDensity>
      <randomWalk>6.4e-06</randomWalk>
      <biasCorrelationTime>600</biasCorrelationTime>
      <magTopic>/mag</magTopic>
    </plugin>

    <plugin name='barometer_plugin' filename='libgazebo_barometer_plugin.so'>
      <robotNamespace/>
      <pubRate>50</pubRate>
      <baroTopic>/baro</baroTopic>
    </plugin>

    <plugin name='motor_plugin' filename='libMotorPlugin.so'>
      <gztopic>/throttle1</gztopic>
      <joint_name>propeller_joint</joint_name>
      <prop_name>propeller</prop_name>
      <diameter>6</diameter>
      <ct>0.09916565  0.00738079 -0.27449944  0.10678074  0.01674628</ct>
      <cp>0.04099138  0.02454836 -0.0241211  -0.13055477  0.04986827</cp>
      <kV>2280</kV>
      <i0>0.465</i0>
      <iMax>20</iMax>
      <r0>0.13</r0>
      <battV>7.4</battV>
      <axis_num>0</axis_num>
    </plugin>

    <plugin name='mavlink_interface' filename='libgazebo_mavlink_interface.so'>
      <robotNamespace></robotNamespace>
      <imuSubTopic>/imu</imuSubTopic>
      <gpsSubTopic>/gps</gpsSubTopic>
      <magSubTopic>/mag</magSubTopic>
      <baroSubTopic>/baro</baroSubTopic>
      <mavlink_addr>INADDR_ANY</mavlink_addr>
      <mavlink_udp_port>14560</mavlink_udp_port>
      <serialEnabled>false</serialEnabled>
      <serialDevice>/dev/ttyACM0</serialDevice>
      <baudRate>921600</baudRate>
      <qgc_addr>INADDR_ANY</qgc_addr>
      <qgc_udp_port>14550</qgc_udp_port>
      <sdk_addr>INADDR_ANY</sdk_addr>
      <sdk_udp_port>14540</sdk_udp_port>
      <hil_mode>false</hil_mode>
      <hil_state_level>false</hil_state_level>
      <enable_lockstep>true</enable_lockstep>
      <use_tcp>true</use_tcp>
      <motorSpeedCommandPubTopic>/gazebo/command/motor_speed</motorSpeedCommandPubTopic>
      <control_channels>
        <channel name="puller">
          <input_index>4</input_index>
          <input_offset>0</input_offset>
          <input_scaling>1</input_scaling>
          <zero_position_disarmed>0</zero_position_disarmed>
          <zero_position_armed>0</zero_position_armed>
          <joint_control_type>position_gztopic</joint_control_type>
          <gztopic>/throttle1</gztopic>
          <joint_name>propeller_joint</joint_name>
        </channel>
        <channel name="rudder">
          <input_index>5</input_index>
          <input_offset>0</input_offset>
          <input_scaling>-0.28</input_scaling>
          <zero_position_disarmed>0</zero_position_disarmed>
          <zero_position_armed>0</zero_position_armed>
          <joint_control_type>position</joint_control_type>
          <joint_name>rudder_joint</joint_name>
          <joint_control_pid>
            <p>10</p>
            <i>0</i>
            <d>0</d>
            <iMax>0</iMax>
            <iMin>0</iMin>
            <cmdMax>0.28</cmdMax>
            <cmdMin>-0.28</cmdMin>
          </joint_control_pid>
        </channel>
        <channel name="elevator">
          <input_index>7</input_index>
          <input_offset>0.6</input_offset>
          <input_scaling>0.28</input_scaling>
          <zero_position_disarmed>0</zero_position_disarmed>
          <zero_position_armed>0</zero_position_armed>
          <joint_control_type>position</joint_control_type>
          <joint_name>elevator_joint</joint_name>
          <joint_control_pid>
            <p>10</p>
            <i>0</i>
            <d>0</d>
            <iMax>0</iMax>
            <iMin>0</iMin>
            <cmdMax>0.28</cmdMax>
            <cmdMin>-0.28</cmdMin>
          </joint_control_pid>
        </channel>
      </control_channels>
    </plugin>

  </model>

</sdf>

<!-- vim: set et fenc=utf-8 ft=xml ff=unix sts=0 sw=2 ts=2 : -->
