<?xml version='1.0'?>
<sdf version='1.6'>
  <model name="miniscout">
    <pose>0 0 0.2 0 0 0</pose>
    <link name='body'>
      <inertial>
        <pose>-0.12 0 0 0 0 0</pose>
        <mass>0.3</mass>
        <inertia>
          <ixx>1e-3</ixx>
          <iyy>1e-3</iyy>
          <izz>1e-3</izz>
        </inertia>
      </inertial>
      <collision name='collision'>
        <geometry>
          <mesh>
            <scale>0.01 0.01 0.01</scale>
            <uri>model://miniscout/meshes/stl/body.stl</uri>
          </mesh>
        </geometry>
        <surface>
          <friction>
            <ode>
              <mu>0.05</mu>
              <mu2>0.05</mu2>
            </ode>
          </friction>
          <contact>
            <ode>
              <max_vel>0.1</max_vel>
              <min_depth>0.001</min_depth>
            </ode>
          </contact>
        </surface>
      </collision>
      <visual name='visual-body'>
        <cast_shadows>0</cast_shadows>
        <geometry>
          <mesh>
            <scale>0.01 0.01 0.01</scale>
            <uri>model://miniscout/meshes/stl/body.stl</uri>
          </mesh>
        </geometry>
        <material>
          <ambient>0.678 0.529 0.384 1</ambient>
          <diffuse>0.678 0.529 0.384 1</diffuse>
          <specular>0.678 0.529 0.384 1</specular>
        </material>
      </visual>
      <visual name='visual-canopy'>
        <cast_shadows>0</cast_shadows>
        <geometry>
          <mesh>
            <scale>0.01 0.01 0.01</scale>
            <uri>model://miniscout/meshes/stl/canopy.stl</uri>
          </mesh>
        </geometry>
        <material>
          <script>
            <name>Gazebo/White</name>
          </script>
        </material>
      </visual>
      <visual name='visual-motor'>
        <cast_shadows>0</cast_shadows>
        <geometry>
          <mesh>
            <scale>0.01 0.01 0.01</scale>
            <uri>model://miniscout/meshes/stl/motor.stl</uri>
          </mesh>
        </geometry>
        <material>
          <script>
            <name>Gazebo/DarkGrey</name>
          </script>
        </material>
      </visual>
    </link>

    <link name='gear'>
      <inertial>
        <pose>-0.07 0 0 0 0 0</pose>
        <mass>0.001</mass>
        <inertia>
          <ixx>1e-4</ixx>
          <iyy>1e-4</iyy>
          <izz>1e-4</izz>
        </inertia>
      </inertial>
      <visual name='visual-gear-wire'>
       <pose>-0.07 0 0 0 0 0</pose>
        <cast_shadows>0</cast_shadows>
        <geometry>
          <mesh>
            <scale>0.01 0.01 0.01</scale>
            <uri>model://miniscout/meshes/stl/gear_wire.stl</uri>
          </mesh>
        </geometry>
        <material>
          <script>
            <name>Gazebo/DarkGrey</name>
          </script>
        </material>
      </visual>
    </link>

    <joint name='gear_joint' type='prismatic'>
      <parent>body</parent>
      <child>gear</child>
      <axis>
        <xyz>0 0 1</xyz>
        <dynamics>
          <spring_stiffness>500.0</spring_stiffness>
          <damping>10</damping>
        </dynamics>
        <limit>
          <lower>-0.05</lower>
          <upper>0.05</upper>
        </limit>
      </axis>
      <physics>
        <ode>
          <implicit_spring_damper>1</implicit_spring_damper>
        </ode>
      </physics>
    </joint>

    <link name='rear_wheel'>
      <pose>-0.40 0 0 0.0 0 0</pose>
      <inertial>
        <mass>0.001</mass>
        <inertia>
          <ixx>1e-6</ixx>
          <iyy>1e-7</iyy>
          <izz>1e-6</izz>
        </inertia>
      </inertial>
      <visual name='rear-left-wheel'>
        <cast_shadows>0</cast_shadows>
        <geometry>
          <mesh>
            <scale>0.005 0.01 0.005</scale>
            <uri>model://miniscout/meshes/stl/wheel.stl</uri>
          </mesh>
        </geometry>
        <material>
          <script>
            <name>Gazebo/Grey</name>
          </script>
        </material>
      </visual>
      <visual name='rear-left-tire'>
        <cast_shadows>0</cast_shadows>
        <geometry>
          <mesh>
            <scale>0.005 0.01 0.005</scale>
            <uri>model://miniscout/meshes/stl/tire.stl</uri>
          </mesh>
        </geometry>
        <material>
          <script>
            <name>Gazebo/White</name>
          </script>
        </material>
      </visual>
      <collision name='collision'>
        <pose>0 0 0 1.57 0 0</pose>
        <geometry>
          <cylinder> 
            <radius>0.025</radius>
            <length>0.01</length>
          </cylinder>
        </geometry>
        <surface>
          <friction>
            <ode>
              <mu>0.3</mu>
              <mu2>0.3</mu2>
            </ode>
          </friction>
          <contact>
            <ode>
              <max_vel>0.1</max_vel>
              <min_depth>0.001</min_depth>
            </ode>
          </contact>
        </surface>
      </collision>
    </link>

    <joint name='rear_wheel_joint' type='revolute'>
      <parent>gear</parent>
      <child>rear_wheel</child>
      <axis>
        <xyz>0 1 0</xyz>
      </axis>
    </joint>

    <link name='left_wheel'>
      <pose>-0.07 -0.05 -0.065 0.0 0 0</pose>
      <inertial>
        <mass>0.001</mass>
        <inertia>
          <ixx>1e-6</ixx>
          <iyy>1e-7</iyy>
          <izz>1e-6</izz>
        </inertia>
      </inertial>
      <visual name='visual-left-wheel'>
        <cast_shadows>0</cast_shadows>
        <geometry>
          <mesh>
            <scale>0.01 0.01 0.01</scale>
            <uri>model://miniscout/meshes/stl/wheel.stl</uri>
          </mesh>
        </geometry>
        <material>
          <script>
            <name>Gazebo/Grey</name>
          </script>
        </material>
      </visual>
      <visual name='visual-left-tire'>
        <cast_shadows>0</cast_shadows>
        <geometry>
          <mesh>
            <scale>0.01 0.01 0.01</scale>
            <uri>model://miniscout/meshes/stl/tire.stl</uri>
          </mesh>
        </geometry>
        <material>
          <script>
            <name>Gazebo/White</name>
          </script>
        </material>
      </visual>
      <collision name='collision'>
        <pose>0 0 0 1.57 0 0</pose>
        <geometry>
          <cylinder> 
            <radius>0.025</radius>
            <length>0.02</length>
          </cylinder>
        </geometry>
        <surface>
          <friction>
            <ode>
              <mu>0.3</mu>
              <mu2>0.3</mu2>
            </ode>
          </friction>
          <contact>
            <ode>
              <max_vel>0.1</max_vel>
              <min_depth>0.001</min_depth>
            </ode>
          </contact>
        </surface>
      </collision>
    </link>

    <joint name='left_wheel_joint' type='revolute'>
      <parent>gear</parent>
      <child>left_wheel</child>
      <axis>
        <xyz>0 1 0</xyz>
      </axis>
    </joint>

    <link name='right_wheel'>
      <pose>-0.07 0.05 -0.065 -0.0 0 0</pose>
      <inertial>
        <mass>0.001</mass>
        <inertia>
          <ixx>1e-6</ixx>
          <iyy>1e-7</iyy>
          <izz>1e-6</izz>
        </inertia>
      </inertial>
      <visual name='visual-right-wheel'>
        <cast_shadows>0</cast_shadows>
        <geometry>
          <mesh>
            <scale>0.01 0.01 0.01</scale>
            <uri>model://miniscout/meshes/stl/wheel.stl</uri>
          </mesh>
        </geometry>
        <material>
          <script>
            <name>Gazebo/Grey</name>
          </script>
        </material>
      </visual>
      <visual name='visual-right-tire'>
        <cast_shadows>0</cast_shadows>
        <geometry>
          <mesh>
            <scale>0.01 0.01 0.01</scale>
            <uri>model://miniscout/meshes/stl/tire.stl</uri>
          </mesh>
        </geometry>
        <material>
          <script>
            <name>Gazebo/White</name>
          </script>
        </material>
      </visual>
      <collision name='collision'>
        <pose>0 0 0 1.57 0 0</pose>
        <geometry>
          <cylinder> 
            <radius>0.025</radius>
            <length>0.02</length>
          </cylinder>
        </geometry>
        <surface>
          <friction>
            <ode>
              <mu>0.3</mu>
              <mu2>0.3</mu2>
            </ode>
          </friction>
          <contact>
            <ode>
              <max_vel>0.1</max_vel>
              <min_depth>0.001</min_depth>
            </ode>
          </contact>
        </surface>
      </collision>
    </link>

    <joint name='right_wheel_joint' type='revolute'>
      <parent>gear</parent>
      <child>right_wheel</child>
      <axis>
        <xyz>0 1 0</xyz>
      </axis>
    </joint>

    <link name='rudder'>
      <pose>-0.421 0 0.023 0 0 0 </pose>
      <inertial>
        <pose>-0.02 0 0 0 0 0</pose>
        <mass>0.001</mass>
        <inertia>
          <ixx>1e-6</ixx>
          <iyy>1e-6</iyy>
          <izz>1e-6</izz>
        </inertia>
      </inertial>
      <visual name='visual'>
        <cast_shadows>0</cast_shadows>
        <geometry>
          <mesh>
            <scale>0.01 0.01 0.01</scale>
            <uri>model://miniscout/meshes/stl/rudder.stl</uri>
          </mesh>
        </geometry>
        <material>
          <ambient>0.678 0.529 0.384 1</ambient>
          <diffuse>0.678 0.529 0.384 1</diffuse>
          <specular>0.678 0.529 0.384 1</specular>
        </material>
      </visual>
    </link>

    <link name='elevators'>
      <pose>-0.421 0 0.023 0 0 0 </pose>
      <inertial>
        <pose>-0.02 0 0 0 0 0</pose>
        <mass>0.001</mass>
        <inertia>
          <ixx>1e-6</ixx>
          <iyy>1e-6</iyy>
          <izz>1e-6</izz>
        </inertia>
      </inertial>
      <visual name='visual'>
        <cast_shadows>0</cast_shadows>
        <geometry>
          <mesh>
            <scale>0.01 0.01 0.01</scale>
            <uri>model://miniscout/meshes/stl/elevator.stl</uri>
          </mesh>
        </geometry>
        <material>
          <ambient>0.678 0.529 0.384 1</ambient>
          <diffuse>0.678 0.529 0.384 1</diffuse>
          <specular>0.678 0.529 0.384 1</specular>
        </material>
      </visual>
    </link>

    <link name='propeller'>
      <pose>0.01 0 0.01 0 0 0</pose>
      <inertial>
        <mass>0.001</mass>
        <inertia>
          <ixx>1e-6</ixx>
          <iyy>1e-6</iyy>
          <izz>1e-6</izz>
        </inertia>
      </inertial>
      <visual name='visual'>
        <pose>0 0 0 0 1.57 0</pose>
        <cast_shadows>0</cast_shadows>
        <geometry>
          <mesh>
            <scale>0.5 0.5 0.5</scale>
            <uri>model://miniscout/meshes/iris_prop_ccw.dae</uri>
          </mesh>
        </geometry>
        <material>
          <script>
            <name>Gazebo/DarkGrey</name>
          </script>
        </material>
      </visual>
    </link>

    <joint name='elevators_joint' type='revolute'>
      <parent>body</parent>
      <child>elevators</child>
      <axis>
        <xyz>0 1 0</xyz>
        <dynamics>
          <damping>1.000</damping>
        </dynamics>
        <limit>
          <lower>-0.53</lower>
          <upper>0.53</upper>
        </limit>
      </axis>
      <physics>
        <ode>
          <implicit_spring_damper>1</implicit_spring_damper>
        </ode>
      </physics>
    </joint>

    <joint name='rudder_joint' type='revolute'>
      <parent>body</parent>
      <child>rudder</child>
      <axis>
        <xyz>0 0 1</xyz>
        <dynamics>
          <damping>1.000</damping>
        </dynamics>
        <limit>
          <lower>-0.53</lower>
          <upper>0.53</upper>
        </limit>
      </axis>
      <physics>
        <ode>
          <implicit_spring_damper>1</implicit_spring_damper>
        </ode>
      </physics>
    </joint>

    <joint name='propeller_joint' type='revolute'>
      <parent>body</parent>
      <child>propeller</child>
      <axis>
        <xyz>1 0 0</xyz>
        <dynamics>
          <damping>1e-5</damping>
        </dynamics>
      </axis>
      <physics>
        <ode>
          <implicit_spring_damper>1</implicit_spring_damper>
        </ode>
      </physics>
    </joint>

  </model>

</sdf>

<!-- vim: set et fenc=utf-8 ft=xml ff=unix sts=0 sw=2 ts=2 : -->
