<?xml version="1.0" ?>
<sdf version="1.6">
  <model name="mini_fixedwing_12">
    <pose>0 0 0.2 0 0 0</pose>
    <link name="fuselage">
      <pose>0 0 0 0 0 0</pose>
      <inertial>
        <pose>0.04 5e-4 -0.01 0 0 0</pose>
        <mass>0.272</mass>
        <inertia>
          <ixx>3.11e-3</ixx>
          <iyy>5.91e-3</iyy>
          <izz>8.86e-3</izz>
        </inertia>
      </inertial>
      <collision name="collision_fuselage">
        <geometry>
          <mesh>
            <scale>1 1 1</scale>
            <uri>model://mini_fixedwing_12/meshes/fuselage.stl</uri>
          </mesh>
        </geometry>
        <surface>
          <friction>
            <ode>
              <mu>0.05</mu>
              <mu2>0.05</mu2>
            </ode>
          </friction>
          <contact>
            <ode>
              <max_vel>0.1</max_vel>
              <min_depth>0.001</min_depth>
            </ode>
          </contact>
        </surface>
      </collision>
      <visual name="visual_fuselage">
        <cast_shadows>1</cast_shadows>
        <material>
          <ambient>0.678 0.529 0.384 1</ambient>
          <diffuse>0.678 0.529 0.384 1</diffuse>
          <specular>0.678 0.529 0.384 1</specular>
        </material>
        <geometry>
          <mesh>
            <scale>1 1 1</scale>
            <uri>model://mini_fixedwing_12/meshes/fuselage.stl</uri>
          </mesh>
        </geometry>
      </visual>

      <!--<visual name='cp_htail'>-->
        <!--<pose>-0.365 0 0.015 0 0 0</pose>-->
        <!--<geometry>-->
          <!--<sphere>-->
            <!--<radius>0.01</radius>-->
          <!--</sphere>-->
        <!--</geometry>-->
      <!--</visual>-->
      <!--<visual name='cp_vtail'>-->
        <!--<pose>-0.375 0 0.05 0 0 0</pose>-->
        <!--<geometry>-->
          <!--<sphere>-->
            <!--<radius>0.01</radius>-->
          <!--</sphere>-->
        <!--</geometry>-->
      <!--</visual>-->
      <!--<visual name='cp_leftwing'>-->
        <!--<pose>0.013 0.2 -0.022 0 0 0</pose>-->
        <!--<geometry>-->
          <!--<sphere>-->
            <!--<radius>0.01</radius>-->
          <!--</sphere>-->
        <!--</geometry>-->
      <!--</visual>-->
      <!--<visual name='cp_rightwing'>-->
        <!--<pose>0.013 -0.2 -0.022 0 0 0</pose>-->
        <!--<geometry>-->
          <!--<sphere>-->
            <!--<radius>0.01</radius>-->
          <!--</sphere>-->
        <!--</geometry>-->
      <!--</visual>-->

    </link>

    <link name='rudder'>
      <pose>-0.39 0 0.016 0 0 3.14</pose>
      <inertial>
        <pose>0.015 0 0.03 0 0 0</pose>
        <mass>0.0018</mass>
        <inertia>
          <ixx>3.36e-4</ixx>
          <iyy>3.44e-4</iyy>
          <izz>7.10e-6</izz>
        </inertia>
      </inertial>
      <visual name='visual_rudder'>
        <material>
          <ambient>0.678 0.529 0.384 1</ambient>
          <diffuse>0.678 0.529 0.384 1</diffuse>
          <specular>0.678 0.529 0.384 1</specular>
        </material>
        <geometry>
          <mesh>
            <scale>1 1 1</scale>
            <uri>model://mini_fixedwing_12/meshes/rudder.stl</uri>
          </mesh>
        </geometry>
      </visual>
    </link>

    <link name='elevator'>
      <pose>-0.39 0 0.005 0 0 3.14</pose>
      <inertial>
        <pose>0.015 0 0 0 0 0</pose>
        <mass>0.002</mass>
        <inertia>
          <ixx>9.41e-4</ixx>
          <iyy>2.50e-5</iyy>
          <izz>9.63e-4</izz>
        </inertia>
      </inertial>
      <visual name='visual_elevator'>
        <material>
          <ambient>0.678 0.529 0.384 1</ambient>
          <diffuse>0.678 0.529 0.384 1</diffuse>
          <specular>0.678 0.529 0.384 1</specular>
        </material>
        <geometry>
          <mesh>
            <scale>1 1 1</scale>
            <uri>model://mini_fixedwing_12/meshes/elevator.stl</uri>
          </mesh>
        </geometry>
      </visual>
    </link>

    <link name='aileron_left'>
      <pose>-0.08 0.320 -0.0174 -0.181 -0.173 1.604</pose>
      <inertial>
        <pose>0 0.015 0 0 0 0</pose>
        <mass>0.0015</mass>
        <inertia>
          <ixx>2.95e-5</ixx>
          <iyy>1.65e-4</iyy>
          <izz>1.94e-4</izz>
        </inertia>
      </inertial>
      <visual name='visual_aileron_left'>
        <material>
          <ambient>0.678 0.529 0.384 1</ambient>
          <diffuse>0.678 0.529 0.384 1</diffuse>
          <specular>0.678 0.529 0.384 1</specular>
        </material>
        <geometry>
          <mesh>
            <scale>0.98 1 1</scale>
            <uri>model://mini_fixedwing_12/meshes/aileron_left.stl</uri>
          </mesh>
        </geometry>
      </visual>
    </link>

    <link name='aileron_right'>
      <pose>-0.08 -0.320 -0.0174 -0.181 0.173 1.538</pose>
      <inertial>
        <pose>0 0.015 0 0 0 0</pose>
        <mass>0.0015</mass>
        <inertia>
          <ixx>2.95e-5</ixx>
          <iyy>1.65e-4</iyy>
          <izz>1.94e-4</izz>
        </inertia>
      </inertial>
      <visual name='visual_aileron_right'>
        <material>
          <ambient>0.678 0.529 0.384 1</ambient>
          <diffuse>0.678 0.529 0.384 1</diffuse>
          <specular>0.678 0.529 0.384 1</specular>
        </material>
        <geometry>
          <mesh>
            <scale>0.98 1 1</scale>
            <uri>model://mini_fixedwing_12/meshes/aileron_right.stl</uri>
          </mesh>
        </geometry>
      </visual>
    </link>

    <link name='left_wheel'>
      <pose>0.1833 0.0605 -0.1030 0 0 0</pose>
      <inertial>
        <pose>0 0 0 0 0 0</pose>
        <mass>0.0025</mass>
        <inertia>
          <ixx>1.4e-5</ixx>
          <iyy>7.64e-6</iyy>
          <izz>1.4e-5</izz>
        </inertia>
      </inertial>
      <collision name='collision_left_wheel'>
        <pose>0 0 0 1.57 0 0</pose>
        <geometry>
          <cylinder> 
            <radius>0.025</radius>
            <length>0.02</length>
          </cylinder>
        </geometry>
        <surface>
          <friction>
            <ode>
              <mu>0.3</mu>
              <mu2>0.3</mu2>
            </ode>
          </friction>
          <contact>
            <ode>
              <max_vel>0.1</max_vel>
              <min_depth>0.001</min_depth>
            </ode>
          </contact>
        </surface>
      </collision>
      <visual name='visual_left_wheel'>
        <material>
          <script>
            <name>Gazebo/DarkGrey</name>
          </script>
        </material>
        <geometry>
          <mesh>
            <scale>1 1 1</scale>
            <uri>model://mini_fixedwing_12/meshes/wheel.stl</uri>
          </mesh>
        </geometry>
      </visual>
    </link>

    <link name='right_wheel'>
      <pose>0.1833 -0.0605 -0.1030 0 0 0</pose>
      <inertial>
        <pose>0 0 0 0 0 0</pose>
        <mass>0.0025</mass>
        <inertia>
          <ixx>1.4e-5</ixx>
          <iyy>7.64e-6</iyy>
          <izz>1.4e-5</izz>
        </inertia>
      </inertial>
      <collision name='collision_right_wheel'>
        <pose>0 0 0 1.57 0 0</pose>
        <geometry>
          <cylinder> 
            <radius>0.025</radius>
            <length>0.02</length>
          </cylinder>
        </geometry>
        <surface>
          <friction>
            <ode>
              <mu>0.3</mu>
              <mu2>0.3</mu2>
            </ode>
          </friction>
          <contact>
            <ode>
              <max_vel>0.1</max_vel>
              <min_depth>0.001</min_depth>
            </ode>
          </contact>
        </surface>
      </collision>
      <visual name='visual_right_wheel'>
        <material>
          <script>
            <name>Gazebo/DarkGrey</name>
          </script>
        </material>
        <geometry>
          <mesh>
            <scale>1 1 1</scale>
            <uri>model://mini_fixedwing_12/meshes/wheel.stl</uri>
          </mesh>
        </geometry>
      </visual>
    </link>

    <link name='propeller'>
      <pose>0.2175 0 -0.0111 0 0 0</pose>
      <inertial>
        <pose>0 0 0 0 0 0.01</pose>
        <mass>0.0084</mass>
        <inertia>
          <ixx>1e-6</ixx>
          <iyy>1e-6</iyy>
          <izz>1e-6</izz>
          <!--<ixx>8e-6</ixx>-->
          <!--<iyy>2.76e-4</iyy>-->
          <!--<izz>2.76e-4</izz>-->
        </inertia>
      </inertial>
      <visual name='visual_propeller'>
        <pose>0 0 0 0 1.57 0</pose>
        <material>
          <script>
            <name>Gazebo/DarkGrey</name>
          </script>
        </material>
        <geometry>
          <mesh>
            <scale>1 1 1</scale>
            <uri>model://mini_fixedwing_12/meshes/prop.stl</uri>
          </mesh>
        </geometry>
      </visual>
    </link>

    <joint name='left_wheel_joint' type='revolute'>
      <parent>fuselage</parent>
      <child>left_wheel</child>
      <axis>
        <xyz>0 1 0</xyz>
        <dynamics>
          <damping>1e-3</damping>
        </dynamics>
      </axis>
    </joint>

    <joint name='right_wheel_joint' type='revolute'>
      <parent>fuselage</parent>
      <child>right_wheel</child>
      <axis>
        <xyz>0 1  0</xyz>
        <dynamics>
          <damping>1e-3</damping>
        </dynamics>
      </axis>
    </joint>

    <joint name='elevator_joint' type='revolute'>
      <parent>fuselage</parent>
      <child>elevator</child>
      <axis>
        <xyz>0 1 0</xyz>
        <dynamics>
          <damping>0.1</damping>
        </dynamics>
      </axis>
      <physics>
        <ode>
          <implicit_spring_damper>1</implicit_spring_damper>
        </ode>
      </physics>
    </joint>

    <joint name='rudder_joint' type='revolute'>
      <parent>fuselage</parent>
      <child>rudder</child>
      <axis>
        <xyz>0 0 1</xyz>
        <dynamics>
          <damping>0.1</damping>
        </dynamics>
      </axis>
      <physics>
        <ode>
          <implicit_spring_damper>1</implicit_spring_damper>
        </ode>
      </physics>
    </joint>

    <joint name='left_aileron_joint' type='revolute'>
      <parent>fuselage</parent>
      <child>aileron_left</child>
      <axis>
        <xyz>1 0 0</xyz>
        <dynamics>
          <damping>1e-3</damping>
        </dynamics>
        <limit>
          <lower>-0.28</lower>
          <upper>0.28</upper>
        </limit>
      </axis>
      <physics>
        <ode>
          <implicit_spring_damper>1</implicit_spring_damper>
        </ode>
      </physics>
    </joint>

    <joint name='right_aileron_joint' type='revolute'>
      <parent>fuselage</parent>
      <child>aileron_right</child>
      <axis>
        <xyz>1 0 0</xyz>
        <dynamics>
          <damping>1e-3</damping>
        </dynamics>
        <limit>
          <lower>-0.28</lower>
          <upper>0.28</upper>
        </limit>
      </axis>
      <physics>
        <ode>
          <implicit_spring_damper>1</implicit_spring_damper>
        </ode>
      </physics>
    </joint>

    <joint name='propeller_joint' type='revolute'>
      <parent>fuselage</parent>
      <child>propeller</child>
      <axis>
        <xyz>1 0 0</xyz>
      </axis>
    </joint>

    <plugin name='leftwing_aero' filename='libLiftDragPlugin.so'>
      <link_name>fuselage</link_name>
      <a0>0.14</a0>
      <cla>7.75</cla>
      <cda>0.49</cda>
      <cma>-0.788</cma>
      <alpha_stal>0.122</alpha_stal>
      <cla_stall>-4</cla_stall>
      <cda_stall>1</cda_stall>
      <cma_stall>0</cma_stall>
      <cp>0.013 0.2 -0.022</cp>
      <area>0.06</area>
      <air_density>1.255</air_density>
      <forward>1 0 0</forward>
      <upward>0 -0.26 0.97</upward>
      <control_joint_name>left_aileron_joint</control_joint_name>
      <control_joint_rad_to_cl>-2.0</control_joint_rad_to_cl>
    </plugin>

    <plugin name='rightwing_aero' filename='libLiftDragPlugin.so'>
      <link_name>fuselage</link_name>
      <a0>0.14</a0>
      <cla>7.75</cla>
      <cda>0.49</cda>
      <cma>-0.788</cma>
      <alpha_stal>0.122</alpha_stal>
      <cla_stall>-4</cla_stall>
      <cda_stall>1</cda_stall>
      <cma_stall>0</cma_stall>
      <cp>0.013 -0.2 -0.022</cp>
      <area>0.06</area>
      <air_density>1.255</air_density>
      <forward>1 0 0</forward>
      <upward>0 0.26 0.97</upward>
      <control_joint_name>right_aileron_joint</control_joint_name>
      <control_joint_rad_to_cl>-2.0</control_joint_rad_to_cl>
    </plugin>

    <plugin name='vtail' filename='libLiftDragPlugin.so'>
      <link_name>fuselage</link_name>
      <a0>0</a0>
      <cla>5.73</cla>
      <cda>0.458</cda>
      <cma>-1.95</cma>
      <alpha_stal>0.174</alpha_stal>
      <cla_stall>-2.65</cla_stall>
      <cda_stall>-0.802</cda_stall>
      <cma_stall>0</cma_stall>
      <cp>-0.365 0 0.05</cp>
      <area>0.03</area>
      <air_density>1.225</air_density>
      <forward>1 0 0</forward>
      <upward>0 1 0</upward>
      <control_joint_name>rudder_joint</control_joint_name>
      <control_joint_rad_to_cl>4.0</control_joint_rad_to_cl>
    </plugin>

    <plugin name='htail' filename='libLiftDragPlugin.so'>
      <link_name>fuselage</link_name>
      <!--modified to balance pitch moment-->
      <a0>0.14</a0>
      <!--<a0>0</a0>-->
      <cla>5.73</cla>
      <cda>0.458</cda>
      <cma>-1.8</cma>
      <alpha_stal>0.174</alpha_stal>
      <cla_stall>-2.65</cla_stall>
      <cda_stall>-0.802</cda_stall>
      <cma_stall>0</cma_stall>
      <cp>-0.36 0 0.015</cp>
      <area>0.03</area>
      <air_density>1.225</air_density>
      <forward>1 0 0</forward>
      <upward>0 0 1</upward>
      <control_joint_name>elevator_joint</control_joint_name>
      <control_joint_rad_to_cl>4.0</control_joint_rad_to_cl>
    </plugin>

    <!--Start PX4 autopilot-->

    <link name='imu_link'>
      <pose>0.04 0 0 0 0 0</pose>
      <inertial>
        <mass>0.01</mass>
        <inertia>
          <ixx>1e-05</ixx>
          <iyy>1e-05</iyy>
          <izz>1e-05</izz>
        </inertia>
      </inertial>
    </link>

    <joint name='imu_joint' type='revolute'>
      <child>imu_link</child>
      <parent>fuselage</parent>
      <axis>
        <xyz>1 0 0</xyz>
        <limit>
          <lower>0</lower>
          <upper>0</upper>
          <effort>0</effort>
          <velocity>0</velocity>
        </limit>
        <dynamics>
          <spring_reference>0</spring_reference>
          <spring_stiffness>0</spring_stiffness>
        </dynamics>
        <use_parent_model_frame>1</use_parent_model_frame>
      </axis>
    </joint>

    <plugin name='gazebo_imu_plugin' filename='libgazebo_imu_plugin.so'>
      <robotNamespace></robotNamespace>
      <linkName>imu_link</linkName>
      <imuTopic>/imu</imuTopic>
      <gyroscopeNoiseDensity>0.0003394</gyroscopeNoiseDensity>
      <gyroscopeRandomWalk>3.8785e-05</gyroscopeRandomWalk>
      <gyroscopeBiasCorrelationTime>1000.0</gyroscopeBiasCorrelationTime>
      <gyroscopeTurnOnBiasSigma>0.0087</gyroscopeTurnOnBiasSigma>
      <accelerometerNoiseDensity>0.004</accelerometerNoiseDensity>
      <accelerometerRandomWalk>0.006</accelerometerRandomWalk>
      <accelerometerBiasCorrelationTime>300.0</accelerometerBiasCorrelationTime>
      <accelerometerTurnOnBiasSigma>0.196</accelerometerTurnOnBiasSigma>
    </plugin>

    <plugin name="gps_plugin" filename="libgazebo_gps_plugin.so">
        <robotNamespace></robotNamespace>
        <gpsNoise>true</gpsNoise>
    </plugin>

    <plugin name='magnetometer_plugin' filename='libgazebo_magnetometer_plugin.so'>
      <robotNamespace/>
      <pubRate>100</pubRate>
      <noiseDensity>0.0004</noiseDensity>
      <randomWalk>6.4e-06</randomWalk>
      <biasCorrelationTime>600</biasCorrelationTime>
      <magTopic>/mag</magTopic>
    </plugin>

    <plugin name='barometer_plugin' filename='libgazebo_barometer_plugin.so'>
      <robotNamespace/>
      <pubRate>50</pubRate>
      <baroTopic>/baro</baroTopic>
    </plugin>

    <plugin name='motor_plugin' filename='libMotorPlugin.so'>
      <gztopic>/throttle1</gztopic>
      <joint_name>propeller_joint</joint_name>
      <prop_name>propeller</prop_name>
      <diameter>6</diameter>
      <ct>0.1893 -0.0023 -0.4128 0.2894 -0.0921</ct>
      <cp>0.1518 -0.2083 0.3144 -0.3632 0.0912</cp>
      <kV>3750</kV>
      <iMax>30</iMax>
      <i0>0.5</i0>
      <r0>0.098</r0>
      <battV>11.1</battV>
      <axis_num>0</axis_num>
      <motor_eff>0.35</motor_eff>
      <verbose>1</verbose>
    </plugin>

    <plugin name='mavlink_interface' filename='libgazebo_mavlink_interface.so'>
      <robotNamespace></robotNamespace>
      <imuSubTopic>/imu</imuSubTopic>
      <gpsSubTopic>/gps</gpsSubTopic>
      <magSubTopic>/mag</magSubTopic>
      <baroSubTopic>/baro</baroSubTopic>
      <mavlink_addr>INADDR_ANY</mavlink_addr>
      <mavlink_udp_port>14560</mavlink_udp_port>
      <serialEnabled>false</serialEnabled>
      <serialDevice>/dev/ttyACM0</serialDevice>
      <baudRate>921600</baudRate>
      <qgc_addr>INADDR_ANY</qgc_addr>
      <qgc_udp_port>14550</qgc_udp_port>
      <sdk_addr>INADDR_ANY</sdk_addr>
      <sdk_udp_port>14540</sdk_udp_port>
      <hil_mode>false</hil_mode>
      <hil_state_level>false</hil_state_level>
      <enable_lockstep>true</enable_lockstep>
      <use_tcp>true</use_tcp>
      <motorSpeedCommandPubTopic>/gazebo/command/motor_speed</motorSpeedCommandPubTopic>
      <control_channels>
        <channel name="rudder">
          <input_index>2</input_index>
          <input_offset>0</input_offset>
          <input_scaling>0.28</input_scaling>
          <zero_position_disarmed>0</zero_position_disarmed>
          <zero_position_armed>0</zero_position_armed>
          <joint_control_type>position</joint_control_type>
          <joint_name>rudder_joint</joint_name>
          <joint_control_pid>
            <p>10</p>
            <i>0</i>
            <d>0</d>
            <iMax>0</iMax>
            <iMin>0</iMin>
            <cmdMax>0.28</cmdMax>
            <cmdMin>-0.28</cmdMin>
          </joint_control_pid>
        </channel>
        <channel name="puller">
          <input_index>4</input_index>
          <input_offset>0</input_offset>
          <input_scaling>1</input_scaling>
          <zero_position_disarmed>0</zero_position_disarmed>
          <zero_position_armed>0</zero_position_armed>
          <joint_control_type>position_gztopic</joint_control_type>
          <gztopic>/throttle1</gztopic>
          <joint_name>propeller_joint</joint_name>
        </channel>
        <channel name="left_aileron">
          <input_index>5</input_index>
          <input_offset>0</input_offset>
          <input_scaling>0.1</input_scaling>
          <zero_position_disarmed>0</zero_position_disarmed>
          <zero_position_armed>0</zero_position_armed>
          <joint_control_type>position</joint_control_type>
          <joint_name>left_aileron_joint</joint_name>
          <joint_control_pid>
            <p>10</p>
            <i>0</i>
            <d>0</d>
            <iMax>0</iMax>
            <iMin>0</iMin>
            <cmdMax>0.28</cmdMax>
            <cmdMin>-0.28</cmdMin>
          </joint_control_pid>
        </channel>
        <channel name="right_aileron">
          <input_index>6</input_index>
          <input_offset>0</input_offset>
          <input_scaling>0.1</input_scaling>
          <zero_position_disarmed>0</zero_position_disarmed>
          <zero_position_armed>0</zero_position_armed>
          <joint_control_type>position</joint_control_type>
          <joint_name>right_aileron_joint</joint_name>
          <joint_control_pid>
            <p>10</p>
            <i>0</i>
            <d>0</d>
            <iMax>0</iMax>
            <iMin>0</iMin>
            <cmdMax>0.28</cmdMax>
            <cmdMin>-0.28</cmdMin>
          </joint_control_pid>
        </channel>
        <channel name="elevator">
          <input_index>7</input_index>
          <input_offset>0</input_offset>
          <input_scaling>-0.1</input_scaling>
          <zero_position_disarmed>0</zero_position_disarmed>
          <zero_position_armed>0</zero_position_armed>
          <joint_control_type>position</joint_control_type>
          <joint_name>elevator_joint</joint_name>
          <joint_control_pid>
            <p>10</p>
            <i>0</i>
            <d>0</d>
            <iMax>0</iMax>
            <iMin>0</iMin>
            <cmdMax>0.28</cmdMax>
            <cmdMin>-0.28</cmdMin>
          </joint_control_pid>
        </channel>
      </control_channels>

    </plugin>

  </model>
</sdf>

<!-- vim: set et fenc=utf-8 ff=unix sts=0 sw=2 ts=2 : -->
